// Task 1

/*try{
    throw new Error("some error occured")
}catch(error){
    console.log(error)
}*/

// Task 2

/*const divison = (a,b) =>{
    return a/b 
}
let a = 5;
let b = 0;
let c = divison(a,b)
if(b === 0){
    
    try{
        throw new Error("denominator cannot be zero")  
    }catch(error){
        console.log(error)
    }
}

// Task 3

try{
throw new Error("some error came")
}catch(error){
console.log(error)
}finally{
console.log("finally block")
}*/

// Task 4

